<?xml version="1.0"?>

<robot name="thor" xmlns:xacro="http://www.ros.org/wiki/xacro">

    <xacro:include filename="$(find thor_description)/urdf/gazebo.xacro" />

    <xacro:include filename="$(find thor_description)/urdf/env.xacro" />

    <link name="dummy_link" />

    <joint name="dummy_joint" type="fixed">
        <origin xyz="0.1 0 0" rpy="0 0 0"/>   <!-- move thor a bit forward on the counter -->
        <parent link="dummy_link" />
        <child link="link_base" />
    </joint>

    <link name="link_base">
        <collision>
            <origin xyz="0 0 0" rpy="0 0 0" />
            <geometry>
                <mesh filename="package://thor_description/meshes/base.stl" scale="0.001 0.001 0.001" />
            </geometry>
        </collision>

        <visual>
            <origin xyz="0 0 0" rpy="0 0 0" />
            <geometry>
                <mesh filename="package://thor_description/meshes/base.stl" scale="0.001 0.001 0.001" />
            </geometry>
            <material name="white">
                <color rgba="1 1 1 1" />
            </material>
        </visual>

        <inertial>
            <mass value="20" />
            <inertia ixx="4778335232" iyy="9956602880" izz="12350248960" ixy="61676072" ixz="-346234336" iyz="-3673513" />
        </inertial>
    </link>


    <joint name="joint_base_art1_yaw" type="revolute">
        <origin xyz="0 0 0.104" rpy="0 0 0" />
        <axis xyz="0 0 1" />
        <parent link="link_base" />
        <child link="link_art1" />
        <limit lower="-3.1415" upper="3.1415" effort="8" velocity="1" />
    </joint>


    <link name="link_art1">
        <collision>
            <origin xyz="0 0 0" rpy="0 0 0" />
            <geometry>
                <mesh filename="package://thor_description/meshes/art1.stl" scale="0.001 0.001 0.001" />
            </geometry>
        </collision>

        <visual>
            <origin xyz="0 0 0" rpy="0 0 0" />
            <geometry>
                <mesh filename="package://thor_description/meshes/art1.stl"
                    scale="0.001 0.001 0.001" />
            </geometry>

            <material name="black">
                <color rgba="0.4 0.4 0.4 1" />
            </material>
        </visual>

        <inertial>
            <mass value="1.6" />
            <inertia ixx="2091996160" iyy="2178797312" izz="1449157760" ixy="-6433.202148" ixz="-9487.117188" iyz="96796960" />
        </inertial>
    </link>

    <joint name="joint_art1_art2_pitch" type="revolute">
        <origin xyz="0 -0.0318752 0.0974304" rpy="1.5707963267948966 -1.5707963267948966 0" />
        <axis xyz="0 0 1" />
        <parent link="link_art1" />
        <child link="link_art2" />
        <limit lower="-1.5707963267948966" upper="1.5707963267948966" effort="20" velocity="1" />
    </joint>

    <link name="link_art2">
        <collision>
            <origin xyz="0 0 0" rpy="0 0 0" />
            <geometry>
                <mesh filename="package://thor_description/meshes/art2.stl" scale="0.001 0.001 0.001" />
            </geometry>
        </collision>

        <visual>
            <origin xyz="0 0 0" rpy="0 0 0" />
            <geometry>
                <mesh filename="package://thor_description/meshes/art2.stl" scale="0.001 0.001 0.001" />
            </geometry>

            <material name="white" />
        </visual>

        <inertial>
            <mass value="0.8" />
            <inertia ixx="2494758144" iyy="5296528896" izz="4277223680" ixy="169831.156250" ixz="-192684608" iyz="-4347370" />l
        </inertial>
    </link>

    <joint name="joint_art2_art3_pitch" type="revolute">
        <origin xyz="0.160 0 0" rpy="0 0 0" />
        <axis xyz="0 0 1" />
        <parent link="link_art2" />
        <child link="link_art3" />
        <limit lower="-1.5707963267948966" upper="1.5707963267948966" effort="8" velocity="1" />
    </joint>

    <link name="link_art3">
        <collision>
            <origin xyz="0 0 0" rpy="0 0 0" />
            <geometry>
                <mesh filename="package://thor_description/meshes/art3.stl" scale="0.001 0.001 0.001" />
            </geometry>
        </collision>

        <visual>
            <origin xyz="0 0 0" rpy="0 0 0" />
            <geometry>
                <mesh filename="package://thor_description/meshes/art3.stl" scale="0.001 0.001 0.001" />
            </geometry>
           

            <material name="black" />
        </visual>

        <inertial>
            <mass value="1.1" />
            <inertia ixx="509821408" iyy="861984512" izz="946194816" ixy="-4423478.5" ixz="1108099" iyz="-62569.3125" />
        </inertial>
    </link>

    <joint name="joint_art3_art4_roll" type="revolute">
        <origin xyz="0.0885 0 -0.035" rpy="0 1.5707963267948966 0" />
        <axis xyz="0 0 1" />
        <parent link="link_art3" />
        <child link="link_art4" />
        <limit lower="-3.1415" upper="3.1415" effort="4" velocity="1" />
    </joint>

    <link name="link_art4">
        <collision>
            <origin xyz="0 0 0" rpy="0 0 0" />
            <geometry>
                <mesh filename="package://thor_description/meshes/art4.stl"
                    scale="0.001 0.001 0.001" />
            </geometry>
        </collision>

        <visual>
            <origin xyz="0 0 0" rpy="0 0 0" />
            <geometry>
                <mesh filename="package://thor_description/meshes/art4.stl"
                    scale="0.001 0.001 0.001" />
            </geometry>

            <material name="white" />
        </visual>

        <inertial>
            <mass value="0.5" />
            <inertia ixx="766526720" iyy="898525120" izz="718228096" ixy="513188.25" ixz="-15419.867188" iyz="546204.625" />
        </inertial>
    </link>

    <joint name="joint_art4_art5_pitch" type="revolute">
        <origin xyz="0 0 0.1" rpy="0 -1.5707963267948966 0" />
        <axis xyz="0 0 1" />
        <parent link="link_art4" />
        <child link="link_art5" />
        <limit lower="-1.5" upper="1.5" effort="6" velocity="1" />
    </joint>

    <link name="link_art5">
        <collision>
            <origin xyz="0 0 0" rpy="0 0 0" />
            <geometry>
                <mesh filename="package://thor_description/meshes/art5.stl"
                    scale="0.001 0.001 0.001" />
            </geometry>
        </collision>

        <visual>
            <origin xyz="0 0 0" rpy="0 0 0" />
            <geometry>
                <mesh filename="package://thor_description/meshes/art5.stl"
                    scale="0.001 0.001 0.001" />
            </geometry>

            <material name="black" />
        </visual>

        <inertial>
            <mass value="0.5" />
            <inertia ixx="22853730" iyy="16640192" izz="36724072" ixy="-103.737335" ixz="-10548.656250" iyz="-0.059193" />
        </inertial>
    </link>

    <joint name="joint_art5_art6_roll" type="revolute">
        <origin xyz="0 0 0" rpy="0 1.5707963267948966 0" />
        <axis xyz="0 0 1" />
        <parent link="link_art5" />
        <child link="link_art6" />
        <limit lower="-3.1415" upper="3.1415" effort="4" velocity="1" />
    </joint>

    <link name="link_art6">
        <collision>
            <origin xyz="0 0 0" rpy="0 0 0" />
            <geometry>
                <mesh filename="package://thor_description/meshes/art6.stl"
                    scale="0.001 0.001 0.001" />
            </geometry>
        </collision>

        <visual>
            <origin xyz="0 0 0" rpy="0 0 0" />
            <geometry>
                <mesh filename="package://thor_description/meshes/art6.stl"
                    scale="0.001 0.001 0.001" />
            </geometry>

            <material name="black" />
        </visual>

        <inertial>
            <mass value="0.5" />
            <inertia ixx="33753776" iyy="33753756" izz="24939260" ixy="-2.472111" ixz="-21.388384" iyz="0.078231" />
        </inertial>
    </link>

    <joint name="joint_arm_hand" type="fixed">
        <origin xyz="0 0.015 0.07" rpy="1.5707963267948966 0 0"  />
        <parent link="link_art6" />
        <child link="link_hand" />
    </joint>
    
    <link name="link_hand">
        <collision>
            <origin xyz="0 0 0" rpy="0 0 0" />
            <geometry>
                <mesh filename="package://thor_description/meshes/hand.stl"
                    scale="0.001 0.001 0.001" />
            </geometry>
        </collision>

        <visual>
            <origin xyz="0 0 0" rpy="0 0 0" />
            <geometry>
                <mesh filename="package://thor_description/meshes/hand.stl"
                    scale="0.001 0.001 0.001" />
            </geometry>

            <material name="black" />
        </visual>

        <inertial>
            <mass value="0.11" />
            <inertia ixx="17803724" iyy="21783168" izz="28014524" ixy="-414543.5" ixz="225471.4375" iyz="-1840743.875" />
        </inertial>
    </link>

    <joint name="joint_hand_finger_left" type="prismatic">
        <parent link="link_hand" />
        <child link="link_finger_left" />
        <origin rpy="0 0 0" xyz="0.05 0.02 0" />
        <axis xyz="-0.5547 0.8321 0"/>
        <limit effort="100" lower="0.0" upper="0.06" velocity="10" />
        <dynamics damping="0.3" friction="0.5" />
    </joint>
    <joint name="joint_hand_finger_right" type="prismatic">
        <parent link="link_hand" />
        <child link="link_finger_right" />
        <origin rpy="0 0 0" xyz="-0.05 0.02 0" />
        <axis xyz="0.5547 0.8321 0"/>
        <limit effort="100" lower="0.0" upper="0.06" velocity="10" />
        <mimic joint="joint_hand_finger_left" />
        <dynamics damping="0.3" friction="0.5" />
    </joint>

    <xacro:gazebo_mimic_joint_plugin name_prefix="joint_hand_finger_right"
        parent_joint="joint_hand_finger_left" mimic_joint="joint_hand_finger_right"
        has_pid="false" />

    <link name="link_finger_left">
        <collision>
            <origin xyz="0 0 0" rpy="0 0 0" />
            <geometry>
                <mesh filename="package://thor_description/meshes/finger.stl"
                    scale="-0.001 0.001 0.001" />
            </geometry>
        </collision>

        <visual>
            <origin xyz="0 0 0" rpy="0 0 0" />
            <geometry>
                <mesh filename="package://thor_description/meshes/finger.stl"
                    scale="-0.001 0.001 0.001" />
            </geometry>

            <material name="white" />
        </visual>

        <inertial>
            <mass value="0.01" />
            <inertia ixx="3358780.25" iyy="627437.875" izz="3410634.5" ixy="-145110.265625" ixz="93.539124" iyz="1280.361816" />
        </inertial>
    </link>

    <link name="link_finger_right">
        <collision>
            <origin xyz="0 0 0" rpy="0 0 0" />
            <geometry>
                <mesh filename="package://thor_description/meshes/finger.stl"
                    scale="0.001 0.001 0.001" />
            </geometry>
        </collision>

        <visual>
            <origin xyz="0 0 0" rpy="0 0 0" />
            <geometry>
                <mesh filename="package://thor_description/meshes/finger.stl"
                    scale="0.001 0.001 0.001" />
            </geometry>

            <material name="white" />
        </visual>

        <inertial>
            <mass value="0.01" />
            <inertia ixx="3358780.25" iyy="627437.875" izz="3410634.5" ixy="-145110.265625" ixz="93.539124" iyz="1280.361816" />
        </inertial>
    </link>

</robot>