<?xml version="1.0" ?>
<!-- =================================================================================== -->
<!-- |    This document was autogenerated by xacro from /media/psf/thor-ros-moveit/src/thor_description/urdf/thor.xacro | -->
<!-- |    EDITING THIS FILE BY HAND IS NOT RECOMMENDED                                 | -->
<!-- =================================================================================== -->
<robot name="thor">
    <gazebo reference="link_base">
        <material>Gazebo/White</material>
        <plugin name="gazebo_ros_control">
            <robotNamespace>/</robotNamespace>
        </plugin>
    </gazebo>
    <gazebo reference="link_art1">
        <material>Gazebo/Black</material>
    </gazebo>
    <gazebo reference="link_art2">
        <material>Gazebo/White</material>
    </gazebo>
    <gazebo reference="link_art3">
        <material>Gazebo/Black</material>
    </gazebo>
    <gazebo reference="link_art4">
        <material>Gazebo/White</material>
    </gazebo>
    <gazebo reference="link_art5">
        <material>Gazebo/Black</material>
    </gazebo>
    <gazebo reference="link_art6">
        <material>Gazebo/Black</material>
    </gazebo>
    <plugin filename="libgazebo_ros_control.so" name="gazebo_ros_control">
        <robotNamespace>/thor</robotNamespace>
        <robotSimType>gazebo_ros_control/DefaultRobotHWSim</robotSimType>
    </plugin>
    <link name="dummy_link" />
    <joint name="dummy_joint" type="fixed">
        <parent link="dummy_link" />
        <child link="link_base" />
    </joint>
    <link name="link_base">
        <collision>
            <origin rpy="0 0 0" xyz="0 0 0" />
            <geometry>
                <mesh filename="package://thor_description/meshes/base.stl" scale="0.001 0.001 0.001" />
            </geometry>
        </collision>
        <visual>
            <origin rpy="0 0 0" xyz="0 0 0" />
            <geometry>
                <mesh filename="package://thor_description/meshes/base.stl" scale="0.001 0.001 0.001" />
            </geometry>
            <material name="white">
                <color rgba="1 1 1 1" />
            </material>
        </visual>
        <inertial>
            <mass value="0.1" />
            <origin xyz="0 0 0" rpy="0 0 0" />
            <inertia ixx="0.03" iyy="0.03" izz="0.03" ixy="0.0" ixz="0.0" iyz="0.0" />
        </inertial>
    </link>
    <joint name="joint_base_art1_yaw" type="revolute">
        <origin rpy="0 0 0" xyz="0 0 0.104" />
        <axis xyz="0 0 1" />
        <parent link="link_base" />
        <child link="link_art1" />
        <limit effort="4" lower="-3.1415" upper="3.1415" velocity="1" />
    </joint>
    <link name="link_art1">
        <collision>
            <origin rpy="0 0 0" xyz="0 0 0" />
            <geometry>
                <mesh filename="package://thor_description/meshes/art1.stl" scale="0.001 0.001 0.001" />
            </geometry>
        </collision>
        <visual>
            <origin rpy="0 0 0" xyz="0 0 0" />
            <geometry>
                <mesh filename="package://thor_description/meshes/art1.stl" scale="0.001 0.001 0.001" />
            </geometry>
            <material name="black">
                <color rgba="0.4 0.4 0.4 1" />
            </material>
        </visual>
        <inertial>
            <mass value="0.1" />
            <origin xyz="0 0 0" rpy="0 0 0" />
            <inertia ixx="0.03" iyy="0.03" izz="0.03" ixy="0.0" ixz="0.0" iyz="0.0" />
        </inertial>
    </link>
    <joint name="joint_art1_art2_pitch" type="revolute">
        <origin rpy="1.5707963267948966 -1.5707963267948966 0" xyz="0 -0.0318752 0.0974304" />
        <axis xyz="0 0 1" />
        <parent link="link_art1" />
        <child link="link_art2" />
        <limit effort="4" lower="-1.5707963267948966" upper="1.5707963267948966" velocity="1" />
    </joint>
    <link name="link_art2">
        <collision>
            <origin rpy="0 0 0" xyz="0 0 0" />
            <geometry>
                <mesh filename="package://thor_description/meshes/art2.stl" scale="0.001 0.001 0.001" />
            </geometry>
        </collision>
        <visual>
            <origin rpy="0 0 0" xyz="0 0 0" />
            <geometry>
                <mesh filename="package://thor_description/meshes/art2.stl" scale="0.001 0.001 0.001" />
            </geometry>
            <material name="white" />
        </visual>
        <inertial>
            <mass value="0.1" />
            <origin xyz="0 0 0" rpy="0 0 0" />
            <inertia ixx="0.03" iyy="0.03" izz="0.03" ixy="0.0" ixz="0.0" iyz="0.0" />
        </inertial>
    </link>
    <joint name="joint_art2_art3_pitch" type="revolute">
        <origin rpy="0 0 0" xyz="0.160 0 0" />
        <axis xyz="0 0 1" />
        <parent link="link_art2" />
        <child link="link_art3" />
        <limit effort="4" lower="-1.5707963267948966" upper="1.5707963267948966" velocity="1" />
    </joint>
    <link name="link_art3">
        <collision>
            <origin rpy="0 0 0" xyz="0 0 0" />
            <geometry>
                <mesh filename="package://thor_description/meshes/art3.stl" scale="0.001 0.001 0.001" />
            </geometry>
        </collision>
        <visual>
            <origin rpy="0 0 0" xyz="0 0 0" />
            <geometry>
                <mesh filename="package://thor_description/meshes/art3.stl" scale="0.001 0.001 0.001" />
            </geometry>
            <material name="black" />
        </visual>
        <inertial>
            <mass value="0.1" />
            <origin xyz="0 0 0" rpy="0 0 0" />
            <inertia ixx="0.03" iyy="0.03" izz="0.03" ixy="0.0" ixz="0.0" iyz="0.0" />
        </inertial>
    </link>
    <joint name="joint_art3_art4_roll" type="revolute">
        <origin rpy="0 1.5707963267948966 0" xyz="0.0885 0 -0.035" />
        <axis xyz="0 0 1" />
        <parent link="link_art3" />
        <child link="link_art4" />
        <limit effort="4" lower="-3.1415" upper="3.1415" velocity="1" />
    </joint>
    <link name="link_art4">
        <collision>
            <origin rpy="0 0 0" xyz="0 0 0" />
            <geometry>
                <mesh filename="package://thor_description/meshes/art4.stl" scale="0.001 0.001 0.001" />
            </geometry>
        </collision>
        <visual>
            <origin rpy="0 0 0" xyz="0 0 0" />
            <geometry>
                <mesh filename="package://thor_description/meshes/art4.stl" scale="0.001 0.001 0.001" />
            </geometry>
            <material name="white" />
        </visual>
        <inertial>
            <mass value="0.1" />
            <origin xyz="0 0 0" rpy="0 0 0" />
            <inertia ixx="0.03" iyy="0.03" izz="0.03" ixy="0.0" ixz="0.0" iyz="0.0" />
        </inertial>
    </link>
    <joint name="joint_art4_art5_pitch" type="revolute">
        <origin rpy="0 -1.5707963267948966 0" xyz="0 0 0.1" />
        <axis xyz="0 0 1" />
        <parent link="link_art4" />
        <child link="link_art5" />
        <limit effort="4" lower="-1.5" upper="1.5" velocity="1" />
    </joint>
    <link name="link_art5">
        <collision>
            <origin rpy="0 0 0" xyz="0 0 0" />
            <geometry>
                <mesh filename="package://thor_description/meshes/art5.stl" scale="0.001 0.001 0.001" />
            </geometry>
        </collision>
        <visual>
            <origin rpy="0 0 0" xyz="0 0 0" />
            <geometry>
                <mesh filename="package://thor_description/meshes/art5.stl" scale="0.001 0.001 0.001" />
            </geometry>
            <material name="black" />
        </visual>
        <inertial>
            <mass value="0.1" />
            <origin xyz="0 0 0" rpy="0 0 0" />
            <inertia ixx="0.03" iyy="0.03" izz="0.03" ixy="0.0" ixz="0.0" iyz="0.0" />
        </inertial>
    </link>
    <joint name="joint_art5_art6_roll" type="revolute">
        <origin rpy="0 1.5707963267948966 0" xyz="0 0 0" />
        <axis xyz="0 0 1" />
        <parent link="link_art5" />
        <child link="link_art6" />
        <limit effort="4" lower="-3.1415" upper="3.1415" velocity="1" />
    </joint>
    <link name="link_art6">
        <collision>
            <origin rpy="0 0 0" xyz="0 0 0" />
            <geometry>
                <mesh filename="package://thor_description/meshes/art6.stl" scale="0.001 0.001 0.001" />
            </geometry>
        </collision>
        <visual>
            <origin rpy="0 0 0" xyz="0 0 0" />
            <geometry>
                <mesh filename="package://thor_description/meshes/art6.stl" scale="0.001 0.001 0.001" />
            </geometry>
            <material name="black" />
        </visual>
        <inertial>
            <mass value="0.1" />
            <origin xyz="0 0 0" rpy="0 0 0" />
            <inertia ixx="0.03" iyy="0.03" izz="0.03" ixy="0.0" ixz="0.0" iyz="0.0" />
        </inertial>
    </link>
    <joint name="joint_arm_hand" type="fixed">
        <origin rpy="1.5707963267948966 0 0" xyz="0 0.015 0.07" />
        <parent link="link_art6" />
        <child link="link_hand" />
    </joint>
    <link name="link_hand">
        <collision>
            <origin rpy="0 0 0" xyz="0 0 0" />
            <geometry>
                <mesh filename="package://thor_description/meshes/hand.stl" scale="0.001 0.001 0.001" />
            </geometry>
        </collision>
        <visual>
            <origin rpy="0 0 0" xyz="0 0 0" />
            <geometry>
                <mesh filename="package://thor_description/meshes/hand.stl" scale="0.001 0.001 0.001" />
            </geometry>
            <material name="black" />
        </visual>
        <inertial>
            <mass value="0.1" />
            <origin xyz="0 0 0" rpy="0 0 0" />
            <inertia ixx="0.03" iyy="0.03" izz="0.03" ixy="0.0" ixz="0.0" iyz="0.0" />
        </inertial>
    </link>
    <joint name="joint_hand_finger_left" type="prismatic">
        <parent link="link_hand" />
        <child link="link_finger_left" />
        <origin rpy="0 0 0" xyz="0.05 0.02 0" />
        <axis xyz="-1 1.5 0" />
        <limit effort="100" lower="0.0" upper="0.03" velocity="0.2" />
        <dynamics damping="0.3" />
    </joint>
    <joint name="joint_hand_finger_right" type="prismatic">
        <parent link="link_hand" />
        <child link="link_finger_right" />
        <origin rpy="0 0 0" xyz="-0.05 0.02 0" />
        <axis xyz="1 1.5 0" />
        <limit effort="100" lower="0.0" upper="0.03" velocity="0.2" />
        <mimic joint="joint_hand_finger_left" />
        <dynamics damping="0.3" />
    </joint>
    <link name="link_finger_left">
        <collision>
            <origin rpy="0 0 0" xyz="0 0 0." />
            <geometry>
                <mesh filename="package://thor_description/meshes/finger.stl" scale="-0.001 0.001 0.001" />
            </geometry>
        </collision>
        <visual>
            <origin rpy="0 0 0" xyz="0 0 0" />
            <geometry>
                <mesh filename="package://thor_description/meshes/finger.stl" scale="-0.001 0.001 0.001" />
            </geometry>
            <material name="white" />
        </visual>
        <inertial>
            <mass value="0.1" />
            <origin xyz="0 0 0" rpy="0 0 0" />
            <inertia ixx="0.03" iyy="0.03" izz="0.03" ixy="0.0" ixz="0.0" iyz="0.0" />
        </inertial>
    </link>
    <link name="link_finger_right">
        <collision>
            <origin rpy="0 0 0" xyz="0 0 0" />
            <geometry>
                <mesh filename="package://thor_description/meshes/finger.stl" scale="0.001 0.001 0.001" />
            </geometry>
        </collision>
        <visual>
            <origin rpy="0 0 0" xyz="0 0 0" />
            <geometry>
                <mesh filename="package://thor_description/meshes/finger.stl" scale="0.001 0.001 0.001" />
            </geometry>
            <material name="white" />
        </visual>
        <inertial>
            <mass value="0.1" />
            <origin xyz="0 0 0" rpy="0 0 0" />
            <inertia ixx="0.03" iyy="0.03" izz="0.03" ixy="0.0" ixz="0.0" iyz="0.0" />
        </inertial>
    </link>
    <transmission name="trans_joint_base_art1_yaw">
        <type>transmission_interface/SimpleTransmission</type>
        <joint name="joint_base_art1_yaw">
            <hardwareInterface>hardware_interface/PositionJointInterface</hardwareInterface>
        </joint>
        <actuator name="joint_base_art1_yaw_motor">
            <hardwareInterface>hardware_interface/PositionJointInterface</hardwareInterface>
            <mechanicalReduction>1</mechanicalReduction>
        </actuator>
    </transmission>
    <transmission name="trans_joint_art1_art2_pitch">
        <type>transmission_interface/SimpleTransmission</type>
        <joint name="joint_art1_art2_pitch">
            <hardwareInterface>hardware_interface/PositionJointInterface</hardwareInterface>
        </joint>
        <actuator name="joint_art1_art2_pitch_motor">
            <hardwareInterface>hardware_interface/PositionJointInterface</hardwareInterface>
            <mechanicalReduction>1</mechanicalReduction>
        </actuator>
    </transmission>
    <transmission name="trans_joint_art2_art3_pitch">
        <type>transmission_interface/SimpleTransmission</type>
        <joint name="joint_art2_art3_pitch">
            <hardwareInterface>hardware_interface/PositionJointInterface</hardwareInterface>
        </joint>
        <actuator name="joint_art2_art3_pitch_motor">
            <hardwareInterface>hardware_interface/PositionJointInterface</hardwareInterface>
            <mechanicalReduction>1</mechanicalReduction>
        </actuator>
    </transmission>
    <transmission name="trans_joint_art3_art4_roll">
        <type>transmission_interface/SimpleTransmission</type>
        <joint name="joint_art3_art4_roll">
            <hardwareInterface>hardware_interface/PositionJointInterface</hardwareInterface>
        </joint>
        <actuator name="joint_art3_art4_roll_motor">
            <hardwareInterface>hardware_interface/PositionJointInterface</hardwareInterface>
            <mechanicalReduction>1</mechanicalReduction>
        </actuator>
    </transmission>
    <transmission name="trans_joint_art4_art5_pitch">
        <type>transmission_interface/SimpleTransmission</type>
        <joint name="joint_art4_art5_pitch">
            <hardwareInterface>hardware_interface/PositionJointInterface</hardwareInterface>
        </joint>
        <actuator name="joint_art4_art5_pitch_motor">
            <hardwareInterface>hardware_interface/PositionJointInterface</hardwareInterface>
            <mechanicalReduction>1</mechanicalReduction>
        </actuator>
    </transmission>
    <transmission name="trans_joint_art5_art6_roll">
        <type>transmission_interface/SimpleTransmission</type>
        <joint name="joint_art5_art6_roll">
            <hardwareInterface>hardware_interface/PositionJointInterface</hardwareInterface>
        </joint>
        <actuator name="joint_art5_art6_roll_motor">
            <hardwareInterface>hardware_interface/PositionJointInterface</hardwareInterface>
            <mechanicalReduction>1</mechanicalReduction>
        </actuator>
    </transmission>
</robot>

