<?xml version="1.0" ?>
<!-- =================================================================================== -->
<!-- |    This document was autogenerated by xacro from /media/psf/thor-ros-moveit/src/thor_description/urdf/thor.xacro | -->
<!-- |    EDITING THIS FILE BY HAND IS NOT RECOMMENDED                                 | -->
<!-- =================================================================================== -->
<robot name="thor">
    <gazebo>
        <plugin filename="libgazebo_ros_control.so" name="gazebo_ros_control">
            <robotNamespace>/</robotNamespace>
            <robotSimType>gazebo_ros_control/DefaultRobotHWSim</robotSimType>
        </plugin>
    </gazebo>
    <gazebo reference="link_base">
        <material>Gazebo/White</material>
    </gazebo>
    <gazebo reference="link_art1">
        <material>Gazebo/Black</material>
    </gazebo>
    <gazebo reference="link_art2">
        <material>Gazebo/White</material>
    </gazebo>
    <gazebo reference="link_art3">
        <material>Gazebo/Black</material>
    </gazebo>
    <gazebo reference="link_art4">
        <material>Gazebo/White</material>
    </gazebo>
    <gazebo reference="link_art5">
        <material>Gazebo/Black</material>
    </gazebo>
    <gazebo reference="link_art6">
        <material>Gazebo/Black</material>
    </gazebo>
    <gazebo reference="link_hand">
        <material>Gazebo/Black</material>
    </gazebo>
    <gazebo reference="link_finger_left">
        <material>Gazebo/White</material>
    </gazebo>
    <gazebo reference="link_finger_right">
        <material>Gazebo/White</material>
    </gazebo>
    <link name="dummy_link" />
    <joint name="dummy_joint" type="fixed">
        <parent link="dummy_link" />
        <child link="link_base" />
    </joint>
    <link name="link_base">
        <collision>
            <origin rpy="0 0 0" xyz="0 0 0" />
            <geometry>
                <mesh filename="package://thor_description/meshes/base.stl" scale="0.001 0.001 0.001" />
            </geometry>
        </collision>
        <visual>
            <origin rpy="0 0 0" xyz="0 0 0" />
            <geometry>
                <mesh filename="package://thor_description/meshes/base.stl" scale="0.001 0.001 0.001" />
            </geometry>
            <material name="white">
                <color rgba="1 1 1 1" />
            </material>
        </visual>
        <inertial>
            <mass value="20" />
            <inertia ixx="4778335232" ixy="61676072" ixz="-346234336" iyy="9956602880" iyz="-3673513" izz="12350248960" />
            <origin xyz="0 0 0" rpy="0 0 0" />
        </inertial>
    </link>
    <joint name="joint_base_art1_yaw" type="revolute">
        <origin rpy="0 0 0" xyz="0 0 0.104" />
        <axis xyz="0 0 1" />
        <parent link="link_base" />
        <child link="link_art1" />
        <limit effort="8" lower="-3.1415" upper="3.1415" velocity="1" />
    </joint>
    <link name="link_art1">
        <collision>
            <origin rpy="0 0 0" xyz="0 0 0" />
            <geometry>
                <mesh filename="package://thor_description/meshes/art1.stl" scale="0.001 0.001 0.001" />
            </geometry>
        </collision>
        <visual>
            <origin rpy="0 0 0" xyz="0 0 0" />
            <geometry>
                <mesh filename="package://thor_description/meshes/art1.stl" scale="0.001 0.001 0.001" />
            </geometry>
            <material name="black">
                <color rgba="0.4 0.4 0.4 1" />
            </material>
        </visual>
        <inertial>
            <mass value="1.6" />
            <inertia ixx="2091996160" ixy="-6433.202148" ixz="-9487.117188" iyy="2178797312" iyz="96796960" izz="1449157760" />
            <origin xyz="0 0 0" rpy="0 0 0" />
        </inertial>
    </link>
    <joint name="joint_art1_art2_pitch" type="revolute">
        <origin rpy="1.5707963267948966 -1.5707963267948966 0" xyz="0 -0.0318752 0.0974304" />
        <axis xyz="0 0 1" />
        <parent link="link_art1" />
        <child link="link_art2" />
        <limit effort="20" lower="-1.5707963267948966" upper="1.5707963267948966" velocity="1" />
    </joint>
    <link name="link_art2">
        <collision>
            <origin rpy="0 0 0" xyz="0 0 0" />
            <geometry>
                <mesh filename="package://thor_description/meshes/art2.stl" scale="0.001 0.001 0.001" />
            </geometry>
        </collision>
        <visual>
            <origin rpy="0 0 0" xyz="0 0 0" />
            <geometry>
                <mesh filename="package://thor_description/meshes/art2.stl" scale="0.001 0.001 0.001" />
            </geometry>
            <material name="white" />
        </visual>
        <inertial>
            <mass value="0.8" />
            <inertia ixx="2494758144" ixy="169831.156250" ixz="-192684608" iyy="5296528896" iyz="-4347370" izz="4277223680" />
            l
            <origin xyz="0 0 0" rpy="0 0 0" />
        </inertial>
    </link>
    <joint name="joint_art2_art3_pitch" type="revolute">
        <origin rpy="0 0 0" xyz="0.160 0 0" />
        <axis xyz="0 0 1" />
        <parent link="link_art2" />
        <child link="link_art3" />
        <limit effort="8" lower="-1.5707963267948966" upper="1.5707963267948966" velocity="1" />
    </joint>
    <link name="link_art3">
        <collision>
            <origin rpy="0 0 0" xyz="0 0 0" />
            <geometry>
                <mesh filename="package://thor_description/meshes/art3.stl" scale="0.001 0.001 0.001" />
            </geometry>
        </collision>
        <visual>
            <origin rpy="0 0 0" xyz="0 0 0" />
            <geometry>
                <mesh filename="package://thor_description/meshes/art3.stl" scale="0.001 0.001 0.001" />
            </geometry>
            <material name="black" />
        </visual>
        <inertial>
            <mass value="1.1" />
            <inertia ixx="509821408" ixy="-4423478.5" ixz="1108099" iyy="861984512" iyz="-62569.3125" izz="946194816" />
            <origin xyz="0 0 0" rpy="0 0 0" />
        </inertial>
    </link>
    <joint name="joint_art3_art4_roll" type="revolute">
        <origin rpy="0 1.5707963267948966 0" xyz="0.0885 0 -0.035" />
        <axis xyz="0 0 1" />
        <parent link="link_art3" />
        <child link="link_art4" />
        <limit effort="4" lower="-3.1415" upper="3.1415" velocity="1" />
    </joint>
    <link name="link_art4">
        <collision>
            <origin rpy="0 0 0" xyz="0 0 0" />
            <geometry>
                <mesh filename="package://thor_description/meshes/art4.stl" scale="0.001 0.001 0.001" />
            </geometry>
        </collision>
        <visual>
            <origin rpy="0 0 0" xyz="0 0 0" />
            <geometry>
                <mesh filename="package://thor_description/meshes/art4.stl" scale="0.001 0.001 0.001" />
            </geometry>
            <material name="white" />
        </visual>
        <inertial>
            <mass value="0.5" />
            <inertia ixx="766526720" ixy="513188.25" ixz="-15419.867188" iyy="898525120" iyz="546204.625" izz="718228096" />
            <origin xyz="0 0 0" rpy="0 0 0" />
        </inertial>
    </link>
    <joint name="joint_art4_art5_pitch" type="revolute">
        <origin rpy="0 -1.5707963267948966 0" xyz="0 0 0.1" />
        <axis xyz="0 0 1" />
        <parent link="link_art4" />
        <child link="link_art5" />
        <limit effort="6" lower="-1.5" upper="1.5" velocity="1" />
    </joint>
    <link name="link_art5">
        <collision>
            <origin rpy="0 0 0" xyz="0 0 0" />
            <geometry>
                <mesh filename="package://thor_description/meshes/art5.stl" scale="0.001 0.001 0.001" />
            </geometry>
        </collision>
        <visual>
            <origin rpy="0 0 0" xyz="0 0 0" />
            <geometry>
                <mesh filename="package://thor_description/meshes/art5.stl" scale="0.001 0.001 0.001" />
            </geometry>
            <material name="black" />
        </visual>
        <inertial>
            <mass value="0.5" />
            <inertia ixx="22853730" ixy="-103.737335" ixz="-10548.656250" iyy="16640192" iyz="-0.059193" izz="36724072" />
            <origin xyz="0 0 0" rpy="0 0 0" />
        </inertial>
    </link>
    <joint name="joint_art5_art6_roll" type="revolute">
        <origin rpy="0 1.5707963267948966 0" xyz="0 0 0" />
        <axis xyz="0 0 1" />
        <parent link="link_art5" />
        <child link="link_art6" />
        <limit effort="4" lower="-3.1415" upper="3.1415" velocity="1" />
    </joint>
    <link name="link_art6">
        <collision>
            <origin rpy="0 0 0" xyz="0 0 0" />
            <geometry>
                <mesh filename="package://thor_description/meshes/art6.stl" scale="0.001 0.001 0.001" />
            </geometry>
        </collision>
        <visual>
            <origin rpy="0 0 0" xyz="0 0 0" />
            <geometry>
                <mesh filename="package://thor_description/meshes/art6.stl" scale="0.001 0.001 0.001" />
            </geometry>
            <material name="black" />
        </visual>
        <inertial>
            <mass value="0.5" />
            <inertia ixx="33753776" ixy="-2.472111" ixz="-21.388384" iyy="33753756" iyz="0.078231" izz="24939260" />
            <origin xyz="0 0 0" rpy="0 0 0" />
        </inertial>
    </link>
    <joint name="joint_arm_hand" type="fixed">
        <origin rpy="1.5707963267948966 0 0" xyz="0 0.015 0.07" />
        <parent link="link_art6" />
        <child link="link_hand" />
    </joint>
    <link name="link_hand">
        <collision>
            <origin rpy="0 0 0" xyz="0 0 0" />
            <geometry>
                <mesh filename="package://thor_description/meshes/hand.stl" scale="0.001 0.001 0.001" />
            </geometry>
        </collision>
        <visual>
            <origin rpy="0 0 0" xyz="0 0 0" />
            <geometry>
                <mesh filename="package://thor_description/meshes/hand.stl" scale="0.001 0.001 0.001" />
            </geometry>
            <material name="black" />
        </visual>
        <inertial>
            <mass value="0.11" />
            <inertia ixx="17803724" ixy="-414543.5" ixz="225471.4375" iyy="21783168" iyz="-1840743.875" izz="28014524" />
            <origin xyz="0 0 0" rpy="0 0 0" />
        </inertial>
    </link>
    <joint name="joint_hand_finger_left" type="prismatic">
        <parent link="link_hand" />
        <child link="link_finger_left" />
        <origin rpy="0 0 0" xyz="0.05 0.02 0" />
        <axis xyz="-0.5547 0.8321 0" />
        <limit effort="100" lower="0.0" upper="0.06" velocity="10" />
        <dynamics damping="0.3" friction="0.5" />
    </joint>
    <joint name="joint_hand_finger_right" type="prismatic">
        <parent link="link_hand" />
        <child link="link_finger_right" />
        <origin rpy="0 0 0" xyz="-0.05 0.02 0" />
        <axis xyz="0.5547 0.8321 0" />
        <limit effort="100" lower="0.0" upper="0.06" velocity="10" />
        <mimic joint="joint_hand_finger_left" />
        <dynamics damping="0.3" friction="0.5" />
    </joint>
    <gazebo>
        <plugin filename="libroboticsgroup_upatras_gazebo_mimic_joint_plugin.so" name="joint_hand_finger_right_mimic_joint_plugin">
            <joint>joint_hand_finger_left</joint>
            <mimicJoint>joint_hand_finger_right</mimicJoint>
            <multiplier>1.0</multiplier>
            <offset>0</offset>
            <sensitiveness>0.0</sensitiveness>
            <maxEffort>1.0</maxEffort>
        </plugin>
    </gazebo>
    <link name="link_finger_left">
        <collision>
            <origin rpy="0 0 0" xyz="0 0 0" />
            <geometry>
                <mesh filename="package://thor_description/meshes/finger.stl" scale="-0.001 0.001 0.001" />
            </geometry>
        </collision>
        <visual>
            <origin rpy="0 0 0" xyz="0 0 0" />
            <geometry>
                <mesh filename="package://thor_description/meshes/finger.stl" scale="-0.001 0.001 0.001" />
            </geometry>
            <material name="white" />
        </visual>
        <inertial>
            <mass value="0.01" />
            <inertia ixx="3358780.25" ixy="-145110.265625" ixz="93.539124" iyy="627437.875" iyz="1280.361816" izz="3410634.5" />
            <origin xyz="0 0 0" rpy="0 0 0" />
        </inertial>
    </link>
    <link name="link_finger_right">
        <collision>
            <origin rpy="0 0 0" xyz="0 0 0" />
            <geometry>
                <mesh filename="package://thor_description/meshes/finger.stl" scale="0.001 0.001 0.001" />
            </geometry>
        </collision>
        <visual>
            <origin rpy="0 0 0" xyz="0 0 0" />
            <geometry>
                <mesh filename="package://thor_description/meshes/finger.stl" scale="0.001 0.001 0.001" />
            </geometry>
            <material name="white" />
        </visual>
        <inertial>
            <mass value="0.01" />
            <inertia ixx="3358780.25" ixy="-145110.265625" ixz="93.539124" iyy="627437.875" iyz="1280.361816" izz="3410634.5" />
            <origin xyz="0 0 0" rpy="0 0 0" />
        </inertial>
    </link>
    <transmission name="trans_joint_base_art1_yaw">
        <type>transmission_interface/SimpleTransmission</type>
        <joint name="joint_base_art1_yaw">
            <hardwareInterface>hardware_interface/PositionJointInterface</hardwareInterface>
        </joint>
        <actuator name="joint_base_art1_yaw_motor">
            <hardwareInterface>hardware_interface/PositionJointInterface</hardwareInterface>
            <mechanicalReduction>1</mechanicalReduction>
        </actuator>
    </transmission>
    <transmission name="trans_joint_art1_art2_pitch">
        <type>transmission_interface/SimpleTransmission</type>
        <joint name="joint_art1_art2_pitch">
            <hardwareInterface>hardware_interface/PositionJointInterface</hardwareInterface>
        </joint>
        <actuator name="joint_art1_art2_pitch_motor">
            <hardwareInterface>hardware_interface/PositionJointInterface</hardwareInterface>
            <mechanicalReduction>1</mechanicalReduction>
        </actuator>
    </transmission>
    <transmission name="trans_joint_art2_art3_pitch">
        <type>transmission_interface/SimpleTransmission</type>
        <joint name="joint_art2_art3_pitch">
            <hardwareInterface>hardware_interface/PositionJointInterface</hardwareInterface>
        </joint>
        <actuator name="joint_art2_art3_pitch_motor">
            <hardwareInterface>hardware_interface/PositionJointInterface</hardwareInterface>
            <mechanicalReduction>1</mechanicalReduction>
        </actuator>
    </transmission>
    <transmission name="trans_joint_art3_art4_roll">
        <type>transmission_interface/SimpleTransmission</type>
        <joint name="joint_art3_art4_roll">
            <hardwareInterface>hardware_interface/PositionJointInterface</hardwareInterface>
        </joint>
        <actuator name="joint_art3_art4_roll_motor">
            <hardwareInterface>hardware_interface/PositionJointInterface</hardwareInterface>
            <mechanicalReduction>1</mechanicalReduction>
        </actuator>
    </transmission>
    <transmission name="trans_joint_art4_art5_pitch">
        <type>transmission_interface/SimpleTransmission</type>
        <joint name="joint_art4_art5_pitch">
            <hardwareInterface>hardware_interface/PositionJointInterface</hardwareInterface>
        </joint>
        <actuator name="joint_art4_art5_pitch_motor">
            <hardwareInterface>hardware_interface/PositionJointInterface</hardwareInterface>
            <mechanicalReduction>1</mechanicalReduction>
        </actuator>
    </transmission>
    <transmission name="trans_joint_art5_art6_roll">
        <type>transmission_interface/SimpleTransmission</type>
        <joint name="joint_art5_art6_roll">
            <hardwareInterface>hardware_interface/PositionJointInterface</hardwareInterface>
        </joint>
        <actuator name="joint_art5_art6_roll_motor">
            <hardwareInterface>hardware_interface/PositionJointInterface</hardwareInterface>
            <mechanicalReduction>1</mechanicalReduction>
        </actuator>
    </transmission>
    <transmission name="trans_joint_hand_finger_left">
        <type>transmission_interface/SimpleTransmission</type>
        <joint name="joint_hand_finger_left">
            <hardwareInterface>hardware_interface/PositionJointInterface</hardwareInterface>
        </joint>
        <actuator name="joint_hand_finger_left_motor">
            <hardwareInterface>hardware_interface/PositionJointInterface</hardwareInterface>
            <mechanicalReduction>1</mechanicalReduction>
        </actuator>
    </transmission>
    <transmission name="trans_joint_hand_finger_right">
        <type>transmission_interface/SimpleTransmission</type>
        <joint name="joint_hand_finger_right">
            <hardwareInterface>hardware_interface/EffortJointInterface</hardwareInterface>
        </joint>
        <actuator name="joint_hand_finger_right_motor">
            <hardwareInterface>hardware_interface/EffortJointInterface</hardwareInterface>
            <mechanicalReduction>1</mechanicalReduction>
        </actuator>
    </transmission>
</robot>

